Traceback (most recent call last):
  File "/home/sroot/.vscode-server/extensions/ms-python.python-2020.12.424452561/pythonFiles/shell_exec.py", line 26, in <module>
    subprocess.check_call(shell_args, stdout=sys.stdout, stderr=sys.stderr)
  File "/usr/lib/python3.8/subprocess.py", line 364, in check_call
    raise CalledProcessError(retcode, cmd)
subprocess.CalledProcessError: Command '['/usr/bin/python3', '/home/sroot/.vscode-server/extensions/ms-python.python-2020.12.424452561/pythonFiles/pyvsc-run-isolated.py', 'pip', 'install', '-U', 'ipykernel', '--user', '/tmp/tmp-8362NLXZfQQKW6yQ.log', '--trusted-host=pypi.python.org', '--trusted-host=pypi.org']' returned non-zero exit status 1.
